#VRML_SIM R2025a utf8

EXTERNPROTO "https://raw.githubusercontent.com/cyberbotics/webots/R2022b/projects/objects/backgrounds/protos/TexturedBackground.proto"
EXTERNPROTO "https://raw.githubusercontent.com/cyberbotics/webots/R2022b/projects/objects/backgrounds/protos/TexturedBackgroundLight.proto"
EXTERNPROTO "https://raw.githubusercontent.com/cyberbotics/webots/R2022b/projects/objects/floors/protos/CircleArena.proto"
EXTERNPROTO "https://raw.githubusercontent.com/cyberbotics/webots/R2025a/projects/objects/apartment_structure/protos/Wall.proto"
EXTERNPROTO "https://raw.githubusercontent.com/cyberbotics/webots/R2025a/projects/objects/factory/containers/protos/WoodenBox.proto"
EXTERNPROTO "https://raw.githubusercontent.com/cyberbotics/webots/R2025a/projects/objects/drinks/protos/Can.proto"
EXTERNPROTO "https://raw.githubusercontent.com/cyberbotics/webots/R2025a/projects/objects/drinks/protos/WaterBottle.proto"

WorldInfo {
}
Viewpoint {
  orientation -0.27995224053961526 -0.20377605337186458 0.9381375501966842 4.339860823671821
  position 0.37540473198435104 2.7411142001087105 3.0341942371703055
  follow "my_robot"
}
TexturedBackground {
}
TexturedBackgroundLight {
}
CircleArena {
  radius 2.5
  wallHeight 0.5
}
Wall {
  translation 1 0 0
  size 0.3 2 0.9
}
Wall {
  translation -1 1 0
  name "wall(1)"
  size 0.3 2 0.9
}
Robot {
  children [
    HingeJoint {
      jointParameters HingeJointParameters {
        axis 0 1 0
        anchor 0 0 0.025
      }
      device [
        RotationalMotor {
          name "left wheel motor"
        }
        PositionSensor {
          name "left wheel sensor"
        }
      ]
      endPoint Solid {
        translation 0 0.045 0.025
        rotation 0 1 0 0
        children [
          DEF WHEEL Pose {
            rotation 1 0 0 1.5707996938995747
            children [
              Shape {
                appearance PBRAppearance {
                  baseColor 1 0 0
                  roughness 1
                  metalness 0
                }
                geometry Cylinder {
                  height 0.01
                  radius 0.025
                }
              }
            ]
          }
        ]
        name "left wheel"
        boundingObject USE WHEEL
        physics Physics {
        }
      }
    }
    HingeJoint {
      jointParameters HingeJointParameters {
        axis 0 1 0
        anchor 0 0 0.025
      }
      device [
        RotationalMotor {
          name "right wheel motor"
        }
        PositionSensor {
          name "right wheel sensor"
        }
      ]
      endPoint Solid {
        translation 0 -0.045 0.025
        rotation 0 1 0 0
        children [
          USE WHEEL
        ]
        name "right wheel"
        boundingObject USE WHEEL
        physics Physics {
        }
      }
    }
    Pose {
      translation 0 0 0.0415
      children [
        Shape {
          appearance PBRAppearance {
            baseColor 0 0 1
            roughness 1
            metalness 0
          }
          geometry DEF BODY Cylinder {
            height 0.08
            radius 0.045
          }
        }
      ]
    }
    Camera {
      translation 0.055 0 0.085
      rotation 0 1 0 0.26
      children [
        Pose {
          rotation 0 1 0 1.5708
          children [
            Shape {
              appearance PBRAppearance {
                baseColor 0.1 0.1 0.1
                roughness 1
                metalness 0
              }
              geometry Box {
                size 0.025 0.035 0.02
              }
            }
          ]
        }
      ]
      name "rgb_camera"
      fieldOfView 1.0472
      width 640
      height 480
    }
    RangeFinder {
      translation 0.055 0 0.085
      rotation 0 1 0 0.26
      children [
        Pose {
          rotation 0 1 0 1.5708
          children [
            Shape {
              appearance PBRAppearance {
                baseColor 0 0.4 1
                roughness 1
                metalness 0
              }
              geometry Box {
                size 0.02 0.03 0.015
              }
            }
          ]
        }
      ]
      name "depth_camera"
      fieldOfView 1.0472
      width 320
      height 240
      minRange 0.05
      maxRange 3
    }
    Lidar {
      translation 0 0 0.105
      children [
        Pose {
          children [
            Shape {
              appearance PBRAppearance {
                baseColor 0.05 0.05 0.05
                roughness 1
                metalness 0
              }
              geometry Cylinder {
                height 0.015
                radius 0.025
              }
            }
          ]
        }
      ]
      horizontalResolution 360
      fieldOfView 6.28319
      numberOfLayers 1
      minRange 0.05
      maxRange 5
    }
    GPS {
      name "gps"
    }
    InertialUnit {
      name "inertial_unit"
    }
    DistanceSensor {
      translation 0.042 0.02 0.063
      rotation 0 0 1 0.5236003061004253
      children [
        DEF SENSOR Pose {
          rotation 0 1 0 1.5708
          children [
            Shape {
              appearance PBRAppearance {
                baseColor 1 1 0
                roughness 1
                metalness 0
              }
              geometry Cylinder {
                height 0.004
                radius 0.008
              }
            }
          ]
        }
      ]
      name "ds0"
      lookupTable [
        0 1020 0
        0.05 1020 0
        0.15 0 0
      ]
      numberOfRays 2
      aperture 1
    }
    DistanceSensor {
      translation 0.042 -0.02 0.063
      rotation 0 0 1 -0.5235996938995747
      children [
        USE SENSOR
      ]
      name "ds1"
      lookupTable [
        0 1020 0
        0.05 1020 0
        0.15 0 0
      ]
      numberOfRays 2
      aperture 1
    }
  ]
  name "my_robot"
  boundingObject Pose {
    translation 0 0 0.0415
    children [
      USE BODY
    ]
  }
  physics Physics {
  }
  controller "<extern>"
}
WoodenBox {
  translation 0 1 0.3
}
WoodenBox {
  translation -1 -0.4 0.3
  name "wooden box(1)"
}
Can {
  translation -2 0 0.06
}
Can {
  translation 0 -1 0.14
  rotation 0.1386748910242063 0.7071059753777807 0.6933760986538704 -0.5235996938995747
  name "can(1)"
}
WaterBottle {
  translation 1 -1.6 0.1
  rotation 0 0.7071067811865475 0.7071067811865475 -0.7854003061004253
}
WaterBottle {
  name "water bottle(1)"
  translation -1.5 -1.3 0.1
  rotation 0 0.7071067811865475 0.7071067811865475 -0.7854003061004253
}
